[2021-07-15 11:37:29,586] {taskinstance.py:896} INFO - Dependencies all met for <TaskInstance: Treino-02.get-data 2021-07-14T11:46:00+00:00 [queued]>
[2021-07-15 11:37:29,606] {taskinstance.py:896} INFO - Dependencies all met for <TaskInstance: Treino-02.get-data 2021-07-14T11:46:00+00:00 [queued]>
[2021-07-15 11:37:29,607] {taskinstance.py:1087} INFO - 
--------------------------------------------------------------------------------
[2021-07-15 11:37:29,607] {taskinstance.py:1088} INFO - Starting attempt 2 of 2
[2021-07-15 11:37:29,607] {taskinstance.py:1089} INFO - 
--------------------------------------------------------------------------------
[2021-07-15 11:37:29,630] {taskinstance.py:1107} INFO - Executing <Task(BashOperator): get-data> on 2021-07-14T11:46:00+00:00
[2021-07-15 11:37:29,641] {standard_task_runner.py:52} INFO - Started process 8710 to run task
[2021-07-15 11:37:29,649] {standard_task_runner.py:76} INFO - Running: ['***', 'tasks', 'run', 'Treino-02', 'get-data', '2021-07-14T11:46:00+00:00', '--job-id', '1593', '--pool', 'default_pool', '--raw', '--subdir', 'DAGS_FOLDER/treino02.py', '--cfg-path', '/tmp/tmplmdlq9gu', '--error-file', '/tmp/tmp8n6j4p55']
[2021-07-15 11:37:29,649] {standard_task_runner.py:77} INFO - Job 1593: Subtask get-data
[2021-07-15 11:37:29,738] {logging_mixin.py:104} INFO - Running <TaskInstance: Treino-02.get-data 2021-07-14T11:46:00+00:00 [running]> on host 07e9e45ed309
[2021-07-15 11:37:29,841] {taskinstance.py:1302} INFO - Exporting the following env vars:
AIRFLOW_CTX_DAG_EMAIL=bruno@***.com.br,bruno@bruno.com.br
AIRFLOW_CTX_DAG_OWNER=Bruno - IGTI
AIRFLOW_CTX_DAG_ID=Treino-02
AIRFLOW_CTX_TASK_ID=get-data
AIRFLOW_CTX_EXECUTION_DATE=2021-07-14T11:46:00+00:00
AIRFLOW_CTX_DAG_RUN_ID=scheduled__2021-07-14T11:46:00+00:00
[2021-07-15 11:37:29,842] {subprocess.py:52} INFO - Tmp dir root location: 
 /tmp
[2021-07-15 11:37:29,843] {subprocess.py:63} INFO - Running command: ['bash', '-c', 'curl https://raw.githubusercontent.com/A3Data/hermione/master/hermione/file_text/train.csv -o ~/train.csv']
[2021-07-15 11:37:29,857] {subprocess.py:75} INFO - Output:
[2021-07-15 11:37:29,873] {subprocess.py:79} INFO -   % Total    % Received % Xferd  Average Speed   Time    Time     Time  Current
[2021-07-15 11:37:29,874] {subprocess.py:79} INFO -                                  Dload  Upload   Total   Spent    Left  Speed
[2021-07-15 11:37:29,930] {subprocess.py:79} INFO -   0     0    0     0    0     0      0      0 --:--:-- --:--:-- --:--:--     0Warning: Failed to create the file /home/***/train.csv: Permission denied
[2021-07-15 11:37:29,931] {subprocess.py:79} INFO - 100    14  100    14    0     0    225      0 --:--:-- --:--:-- --:--:--   225
[2021-07-15 11:37:29,931] {subprocess.py:79} INFO - curl: (23) Failed writing body (0 != 14)
[2021-07-15 11:37:29,932] {subprocess.py:83} INFO - Command exited with return code 23
[2021-07-15 11:37:29,954] {taskinstance.py:1501} ERROR - Task failed with exception
Traceback (most recent call last):
  File "/home/airflow/.local/lib/python3.6/site-packages/airflow/models/taskinstance.py", line 1157, in _run_raw_task
    self._prepare_and_execute_task_with_callbacks(context, task)
  File "/home/airflow/.local/lib/python3.6/site-packages/airflow/models/taskinstance.py", line 1331, in _prepare_and_execute_task_with_callbacks
    result = self._execute_task(context, task_copy)
  File "/home/airflow/.local/lib/python3.6/site-packages/airflow/models/taskinstance.py", line 1361, in _execute_task
    result = task_copy.execute(context=context)
  File "/home/airflow/.local/lib/python3.6/site-packages/airflow/operators/bash.py", line 180, in execute
    raise AirflowException('Bash command failed. The command returned a non-zero exit code.')
airflow.exceptions.AirflowException: Bash command failed. The command returned a non-zero exit code.
[2021-07-15 11:37:29,956] {taskinstance.py:1551} INFO - Marking task as FAILED. dag_id=Treino-02, task_id=get-data, execution_date=20210714T114600, start_date=20210715T113729, end_date=20210715T113729
[2021-07-15 11:37:30,020] {local_task_job.py:151} INFO - Task exited with return code 1
